Workbook

Sheet Portada
B2: Marcas Stellantis · Post-venta DCA
B3: Ventas + OR Servicio + Refacciones + Tiempo a 1er servicio
B5: Fecha de corte | C5: 15-jun-2026
B6: Fuente | C6: DCA · cubos 30003 + 30008 (BITAM Artus)
B7: Periodo | C7: 2025-01-01 a 2026-06-15
B8: Marcas | C8: RAM · PEUGEOT · JEEP · DODGE · FIAT
B10: Contenido por hoja (todas con fórmulas vivas)
B11: §1 Ventas mensuales | C11: Subtotales/acumulado SUM. Total uds = sumade 5 marcas
B12: §2 OR Servicio mensuales | C12: Igual a §1 con OR distinta
B13: §3 Ratio OR sobre Venta | C13: OR y Uds linkeados a §1/§2. Ratio = OR/Uds
B14: §4 Valor refacciones | C14: Total = SUM. Revenue linkeado a §1. % = Total/Revenue
B15: §5 Tiempo a 1er servicio | C15: % Cobertura = Con servicio / Vendidos
B16: §5 Buckets de días | C16: Total por bucket = SUM marcas
B18: Hallazgo central | C18: STL retiene 14-21% de autos vendidos (vs 66-79% Chinas). PEUGEOT 46.8% único caso saludable. Brecha estructural de retención FCA.

Sheet Metodología
A1: Metodología · cómo se calculó cada número
A2: Cada hoja del libro usa fórmulas vivas: si editas un mes, los totales/ratios/% recalculan solos. Aquí está la receta exacta de cada cálculo, con la celda dónde lo verificas.
A4: 0. Fuente, periodo y filtros base
A5: Tema | B5: Detalle | C5: Cubo / Campo | D5: Notas
A6: Fuente | B6: BITAM Artus · D1 bitam-mkt (cubos 30003+30008) | C6: — | D6: Misma capa F (DCA) que reporte chinas
A7: Marcas STL | B7: RAM, PEUGEOT, JEEP, DODGE, FIAT (Marca del auto) | C7: D_67 Marca | D7: Catálogo STL en DCA: 5 marcas en GP (ALFA ROMEO presente con 1 row residual)
A8: Periodo | B8: 2025-01-01 a 2026-06-15 (parcial) | C8: D_25 Fecha Facturación | D8: Junio 2026 parcial — no citar aislado sin validar
A9: Filtro Servicio | B9: tipo_orden NOT LIKE '%INTERNA%' AND NOT LIKE 'INTERNO%' AND NOT LIKE 'DEV%' | C9: D_50 Tipo Orden | D9: Incluye Público, Previa Entrega, Aseguradoras, Garantías, HYP, Filiales, Reclamaciones
A10: OR distinta | B10: DISTINCT por Folio Orden Reparación | C10: D_31 Folio OR | D10: —
A12: §1 Ventas mensuales — cómo se calcula
A13: Métrica | B13: Fórmula en Excel | C13: Origen del dato | D13: Lectura
A14: Uds por marca por mes (B–F) | B14: Valor crudo del cubo 30003 (COUNT VINs nuevos) | C14: 30003 → cubo_30003_ventas en D1 | D14: Filtrado por nuevo_usado='AUTOS NUEVOS' + marca STL
A15: $ por marca por mes (G–K) | B15: Valor crudo del cubo 30003 (SUM importe_factura REAL) | C15: 30003 · I_30217 / parsed | D15: ='$250,000' → 250000 al ingestar
A16: Total uds del mes (L) | B16: =SUM(B:F) | C16: Fórmula viva | D16: Suma horizontal de las 5 marcas
A17: Total 2025 / 2026 YTD / Acumulado | B17: SUMs verticales | C17: Fórmula viva | D17: Acumulado = sub25 + subYTD
A19: §2 OR Servicio mensuales — cómo se calcula
A20: Métrica | B20: Fórmula en Excel | C20: Origen del dato | D20: Lectura
A21: OR por marca por mes (B–F) | B21: COUNT DISTINCT folio_or del mes × marca | C21: 30008 → cubo_30008_servicio en D1 | D21: Excluye INTERNA/INTERNO/DEV
A22: Total OR / Subtotales / Acumulado | B22: SUM en filas y columnas | C22: Fórmula viva | D22: Acumulado alimenta §3
A24: §3 Ratio OR / Venta — cómo se calcula
A25: Métrica | B25: Fórmula en Excel | C25: Origen del dato | D25: Lectura
A26: OR distintas (col B) | B26: ='§2 OR Servicio mensuales'!<col_marca>22 | C26: Link a §2 acumulado | D26: Si editas §2, se actualiza
A27: Uds vendidas (col C) | B27: ='§1 Ventas mensuales'!<col_marca>22 | C27: Link a §1 acumulado | D27: Si editas §1, se actualiza
A28: Ratio OR/Venta (col D) | B28: =B/C | C28: Fórmula viva | D28: PEUGEOT alto por parque legacy (10+ años en GP)
A30: §4 Valor refacciones — cómo se calcula
A31: Métrica | B31: Fórmula en Excel | C31: Origen del dato | D31: Lectura
A32: Servicio $ (col B) | B32: SUM I_30498 Vta $ Serv del cubo 30008 | C32: 30008 · vta_serv | D32: Mano de obra de servicio
A33: Refacciones $ (col C) | B33: SUM I_30500 Vta $ Ref | C33: 30008 · vta_ref | D33: Piezas en OR de servicio
A34: Hojalatería $ (col D) | B34: SUM I_30499 Vta $ HyP | C34: 30008 · vta_hyp | D34: —
A35: Total post-venta $ (col E) | B35: =B+C+D | C35: Fórmula viva | D35: —
A36: Revenue venta $ (col F) | B36: =§1 acumulado fila 22 | C36: Link | D36: Ingreso de venta nueva por marca
A37: % vs Revenue (col G) | B37: =E/F | C37: Fórmula viva | D37: Bench NADA US 8–12%; STL en 6.67%
A38: TOTAL STL | B38: SUM por col + % calc | C38: Fórmula viva | D38: Agregado 5 marcas
A40: §5 Tiempo a 1er servicio — cómo se calcula
A41: Métrica | B41: Fórmula en Excel | C41: Origen del dato | D41: Lectura
A42: Método base | B42: JOIN VIN limpio entre 30003 y 30008. Para cada VIN: MIN(fecha_servicio) − MIN(fecha_venta) | C42: SQL contra D1 | D42: Solo si fecha_servicio ≥ fecha_venta
A43: Vendidos (col B) / Con servicio (col C) | B43: Pre-calculado por SQL | C43: — | D43: —
A44: % Cobertura (col D) | B44: =C/B | C44: Fórmula viva | D44: FCA (RAM/JEEP/DODGE/FIAT) en 14-21%; PEUGEOT 47%
A45: Promedio / Mediana | B45: AVG y MEDIAN días | C45: SQL | D45: MEDIANA es indicador robusto
A46: TOTAL STL | B46: SUM, % = C/B, promedio ponderado (SUMPRODUCT/SUM) | C46: Mezcla viva + reporte | D46: Mediana del total = 127 d (no agregable)
...

Sheet §1 Ventas mensuales
A1: Mes | B1: RAM uds | C1: PEUGEOT uds | D1: JEEP uds | E1: DODGE uds | F1: FIAT uds | G1: RAM $ | H1: PEUGEOT $ | I1: JEEP $ | J1: DODGE $ | K1: FIAT $ | L1: Total uds
A2: 2025/01 | B2: 19 | C2: 60 | D2: 11 | E2: 7 | F2: 6 | G2: 8495592 | H2: 23370699 | I2: 9946641 | J2: 3178146 | K2: 2638800 | L2: =SUM(B2:F2)
A3: 2025/02 | B3: 19 | C3: 29 | D3: 6 | E3: 13 | F3: 6 | G3: 11730274 | H3: 11026511 | I3: 4842709 | J3: 5097123 | K3: 2608400 | L3: =SUM(B3:F3)
A4: 2025/03 | B4: 16 | C4: 26 | D4: 9 | E4: 4 | F4: 3 | G4: 8217277 | H4: 10417403 | I4: 9611416 | J4: 1685212 | K4: 316224 | L4: =SUM(B4:F4)
A5: 2025/04 | B5: 21 | C5: 35 | D5: 8 | E5: 5 | F5: 9 | G5: 14156090 | H5: 15047784 | I5: 7823625 | J5: 2234503 | K5: 1726118 | L5: =SUM(B5:F5)
A6: 2025/05 | B6: 24 | C6: 65 | D6: 18 | E6: 5 | F6: 14 | G6: 17015072 | H6: 26453222 | I6: 13304803 | J6: 1677387 | K6: 2566347 | L6: =SUM(B6:F6)
A7: 2025/06 | B7: 20 | C7: 52 | D7: 13 | E7: 7 | F7: 5 | G7: 10670582 | H7: 19494580 | I7: 15460847 | J7: 2970111 | K7: 1825204 | L7: =SUM(B7:F7)
A8: 2025/07 | B8: 28 | C8: 40 | D8: 18 | E8: 7 | F8: 8 | G8: 9447494 | H8: 15809590 | I8: 7043443 | J8: 531955 | K8: 1686483 | L8: =SUM(B8:F8)
A9: 2025/08 | B9: 50 | C9: 40 | D9: 9 | E9: 24 | F9: 0 | G9: 26262764 | H9: 16404870 | I9: 8220239 | J9: 10286612 | K9: 0 | L9: =SUM(B9:F9)
A10: 2025/09 | B10: 84 | C10: 35 | D10: 20 | E10: 38 | F10: 4 | G10: 17153006 | H10: 16989654 | I10: 20090291 | J10: 6097122 | K10: 1750200 | L10: =SUM(B10:F10)
A11: 2025/10 | B11: 17 | C11: 41 | D11: 16 | E11: 130 | F11: 5 | G11: 7188766 | H11: 13049361 | I11: 12065660 | J11: 53344370 | K11: 292629 | L11: =SUM(B11:F11)
A12: 2025/11 | B12: 80 | C12: 27 | D12: 31 | E12: 31 | F12: 4 | G12: 41380435 | H12: 12226637 | I12: 27191679 | J12: 11901295 | K12: 1512934 | L12: =SUM(B12:F12)
A13: 2025/12 | B13: 86 | C13: 42 | D13: 16 | E13: 12 | F13: 1 | G13: 56215300 | H13: 17138135 | I13: 11096487 | J13: 4103005 | K13: 340900 | L13: =SUM(B13:F13)
A14: Total 2025 | B14: =SUM(B2:B13) | C14: =SUM(C2:C13) | D14: =SUM(D2:D13) | E14: =SUM(E2:E13) | F14: =SUM(F2:F13) | G14: =SUM(G2:G13) | H14: =SUM(H2:H13) | I14: =SUM(I2:I13) | ... L14: =SUM(L2:L13)
A15: 2026/01 | B15: 52 | C15: 25 | D15: 11 | E15: 19 | F15: 1 | G15: 14733194 | H15: 11932581 | I15: 7915937 | J15: 7572885 | K15: 375900 | L15: =SUM(B15:F15)
A16: 2026/02 | B16: 34 | C16: 52 | D16: 20 | E16: 8 | F16: 6 | G16: 12580195 | H16: 18222454 | I16: 10128621 | J16: 1842200 | K16: 2317114 | L16: =SUM(B16:F16)
A17: 2026/03 | B17: 63 | C17: 52 | D17: 16 | E17: 7 | F17: 3 | G17: 29515749 | H17: 17194972 | I17: 12066298 | J17: 2505723 | K17: 375900 | L17: =SUM(B17:F17)
A18: 2026/04 | B18: 65 | C18: 24 | D18: 13 | E18: 5 | F18: 1 | G18: 28349775 | H18: 10966766 | I18: 8650057 | J18: 1553800 | K18: 422900 | L18: =SUM(B18:F18)
A19: 2026/05 | B19: 78 | C19: 41 | D19: 13 | E19: 8 | F19: 2 | G19: 31776801 | H19: 17200129 | I19: 10535212 | J19: 3712200 | K19: 737976 | L19: =SUM(B19:F19)
A20: 2026/06 * | B20: 16 | C20: 12 | D20: 2 | E20: 4 | F20: 0 | G20: 6518444 | H20: 5406387 | I20: 1496800 | J20: 1589203 | K20: 0 | L20: =SUM(B20:F20)
A21: Total 2026 YTD | B21: =SUM(B15:B20) | C21: =SUM(C15:C20) | D21: =SUM(D15:D20) | E21: =SUM(E15:E20) | F21: =SUM(F15:F20) | G21: =SUM(G15:G20) | H21: =SUM(H15:H20) | I21: =SUM(I15:I20) | ... L21: =SUM(L15:L20)
A22: Acumulado 2025+26 YTD | B22: =B14+B21 | C22: =C14+C21 | D22: =D14+D21 | E22: =E14+E21 | F22: =F14+F21 | G22: =G14+G21 | H22: =H14+H21 | I22: =I14+I21 | ... L22: =L14+L21
A24: (*) Junio 2026 parcial al 15-jun. Validar con Inés antes de citar.

Sheet §2 OR Servicio mensuales
A1: Mes | B1: RAM | C1: PEUGEOT | D1: JEEP | E1: DODGE | F1: FIAT | G1: Total OR
A2: 2025/01 | B2: 21 | C2: 576 | D2: 34 | E2: 17 | F2: 16 | G2: =SUM(B2:F2)
A3: 2025/02 | B3: 17 | C3: 356 | D3: 22 | E3: 9 | F3: 3 | G3: =SUM(B3:F3)
A4: 2025/03 | B4: 24 | C4: 393 | D4: 38 | E4: 13 | F4: 10 | G4: =SUM(B4:F4)
A5: 2025/04 | B5: 25 | C5: 301 | D5: 38 | E5: 16 | F5: 6 | G5: =SUM(B5:F5)
A6: 2025/05 | B6: 9 | C6: 414 | D6: 46 | E6: 16 | F6: 7 | G6: =SUM(B6:F6)
A7: 2025/06 | B7: 27 | C7: 359 | D7: 28 | E7: 15 | F7: 11 | G7: =SUM(B7:F7)
A8: 2025/07 | B8: 40 | C8: 393 | D8: 44 | E8: 17 | F8: 11 | G8: =SUM(B8:F8)
A9: 2025/08 | B9: 40 | C9: 435 | D9: 42 | E9: 12 | F9: 11 | G9: =SUM(B9:F9)
A10: 2025/09 | B10: 32 | C10: 365 | D10: 38 | E10: 10 | F10: 6 | G10: =SUM(B10:F10)
A11: 2025/10 | B11: 54 | C11: 406 | D11: 53 | E11: 19 | F11: 8 | G11: =SUM(B11:F11)
A12: 2025/11 | B12: 27 | C12: 365 | D12: 53 | E12: 13 | F12: 2 | G12: =SUM(B12:F12)
A13: 2025/12 | B13: 49 | C13: 294 | D13: 51 | E13: 24 | F13: 10 | G13: =SUM(B13:F13)
A14: Total 2025 | B14: =SUM(B2:B13) | C14: =SUM(C2:C13) | D14: =SUM(D2:D13) | E14: =SUM(E2:E13) | F14: =SUM(F2:F13) | G14: =SUM(G2:G13)
A15: 2026/01 | B15: 47 | C15: 412 | D15: 44 | E15: 18 | F15: 6 | G15: =SUM(B15:F15)
A16: 2026/02 | B16: 41 | C16: 315 | D16: 57 | E16: 19 | F16: 6 | G16: =SUM(B16:F16)
A17: 2026/03 | B17: 65 | C17: 407 | D17: 62 | E17: 18 | F17: 15 | G17: =SUM(B17:F17)
A18: 2026/04 | B18: 34 | C18: 363 | D18: 54 | E18: 27 | F18: 15 | G18: =SUM(B18:F18)
A19: 2026/05 | B19: 73 | C19: 390 | D19: 65 | E19: 24 | F19: 8 | G19: =SUM(B19:F19)
A20: 2026/06 * | B20: 34 | C20: 134 | D20: 24 | E20: 19 | F20: 10 | G20: =SUM(B20:F20)
A21: Total 2026 YTD | B21: =SUM(B15:B20) | C21: =SUM(C15:C20) | D21: =SUM(D15:D20) | E21: =SUM(E15:E20) | F21: =SUM(F15:F20) | G21: =SUM(G15:G20)
A22: Acumulado 2025+26 YTD | B22: =B14+B21 | C22: =C14+C21 | D22: =D14+D21 | E22: =E14+E21 | F22: =F14+F21 | G22: =G14+G21

Sheet §3 Ratio OR sobre Venta
A1: Marca | B1: OR distintas | C1: Uds vendidas | D1: Ratio OR/Venta
A2: RAM | B2: ='§2 OR Servicio mensuales'!B22 | C2: ='§1 Ventas mensuales'!B22 | D2: =B2/C2
A3: PEUGEOT | B3: ='§2 OR Servicio mensuales'!C22 | C3: ='§1 Ventas mensuales'!C22 | D3: =B3/C3
A4: JEEP | B4: ='§2 OR Servicio mensuales'!D22 | C4: ='§1 Ventas mensuales'!D22 | D4: =B4/C4
A5: DODGE | B5: ='§2 OR Servicio mensuales'!E22 | C5: ='§1 Ventas mensuales'!E22 | D5: =B5/C5
A6: FIAT | B6: ='§2 OR Servicio mensuales'!F22 | C6: ='§1 Ventas mensuales'!F22 | D6: =B6/C6

Sheet §4 Valor refacciones
A1: Marca | B1: Servicio $ | C1: Refacciones $ | D1: Hojalatería $ | E1: Total post-venta $ | F1: Revenue venta $ | G1: % vs Revenue
A2: RAM | B2: 1228227 | C2: 1888998 | D2: 400526 | E2: =B2+C2+D2 | F2: ='§1 Ventas mensuales'!G22 | G2: =E2/F2
A3: PEUGEOT | B3: 15459177 | C3: 27692732 | D3: 8413937 | E3: =B3+C3+D3 | F3: ='§1 Ventas mensuales'!H22 | G3: =E3/F3
A4: JEEP | B4: 1696383 | C4: 3984464 | D4: 745430 | E4: =B4+C4+D4 | F4: ='§1 Ventas mensuales'!I22 | G4: =E4/F4
A5: DODGE | B5: 556906 | C5: 787302 | D5: 766679 | E5: =B5+C5+D5 | F5: ='§1 Ventas mensuales'!J22 | G5: =E5/F5
A6: FIAT | B6: 287485 | C6: 439124 | D6: 364086 | E6: =B6+C6+D6 | F6: ='§1 Ventas mensuales'!K22 | G6: =E6/F6
A7: TOTAL STL | B7: =SUM(B2:B6) | C7: =SUM(C2:C6) | D7: =SUM(D2:D6) | E7: =SUM(E2:E6) | F7: =SUM(F2:F6) | G7: =E7/F7

Sheet §5 Tiempo a 1er servicio
A1: Marca | B1: Vendidos en periodo | C1: Con ≥1 servicio | D1: % Cobertura | E1: Promedio días | F1: Mediana días | G1: Min | H1: Max
A2: RAM | B2: 633 | C2: 94 | D2: =C2/B2 | E2: 143 | F2: 120 | G2: 0 | H2: 434
A3: PEUGEOT | B3: 600 | C3: 281 | D3: =C3/B3 | E3: 145 | F3: 124 | G3: 0 | H3: 486
A4: JEEP | B4: 207 | C4: 44 | D4: =C4/B4 | E4: 143 | F4: 108 | G4: 0 | H4: 415
A5: DODGE | B5: 272 | C5: 40 | D5: =C5/B5 | E5: 185 | F5: 180 | G5: 6 | H5: 470
A6: FIAT | B6: 56 | C6: 8 | D6: =C6/B6 | E6: 152 | F6: 64 | G6: 0 | H6: 416
A7: TOTAL STL | B7: =SUM(B2:B6) | C7: =SUM(C2:C6) | D7: =C7/B7 | E7: =ROUND(SUMPRODUCT(E2:E6,C2:C6)/C7,0) | F7: 127 | G7: =MIN(G2:G6) | H7: =MAX(H2:H6)

Sheet §5 Buckets de días
A1: Bucket | B1: RAM | C1: PEUGEOT | D1: JEEP | E1: DODGE | F1: FIAT | G1: Total
A2: 0–30 d | B2: 21 | C2: 68 | D2: 11 | E2: 3 | F2: 1 | G2: =SUM(B2:F2)
A3: 31–90 d | B3: 22 | C3: 46 | D3: 9 | E3: 8 | F3: 4 | G3: =SUM(B3:F3)
A4: 91–180 d | B4: 16 | C4: 63 | D4: 6 | E4: 9 | F4: 0 | G4: =SUM(B4:F4)
A5: 181–365 d | B5: 32 | C5: 88 | D5: 15 | E5: 15 | F5: 2 | G5: =SUM(B5:F5)
A6: 366+ d | B6: 3 | C6: 16 | D6: 3 | E6: 5 | F6: 1 | G6: =SUM(B6:F6)
A7: Total con servicio | B7: =SUM(B2:B6) | C7: =SUM(C2:C6) | D7: =SUM(D2:D6) | E7: =SUM(E2:E6) | F7: =SUM(F2:F6) | G7: =SUM(G2:G6)
