Workbook

Sheet Portada
B2: Marcas Chinas · Post-venta DCA
B3: Ventas + Órdenes de Servicio + Refacciones + Tiempo a 1er servicio
B5: Fecha de corte | C5: 15-jun-2026
B6: Fuente | C6: DCA · cubos 30003 + 30008 (BITAM Artus)
B7: Periodo | C7: 2025-01-01 a 2026-06-15
B8: Marcas | C8: GAC · CHANGAN · GWM
B10: Contenido por hoja (todas con fórmulas vivas)
B11: §1 Ventas mensuales | C11: Subtotales/acumulado por SUM, Total uds por suma de marcas
B12: §2 OR Servicio mensuales | C12: Igual a §1 — subtotales SUM, Total OR por suma de marcas
B13: §3 Ratio OR sobre Venta | C13: OR y Uds linkeados a §1/§2. Ratio = OR/Uds
B14: §4 Valor refacciones | C14: Total = SUM. Revenue linkeado a §1. % = Total/Revenue
B15: §5 Tiempo a 1er servicio | C15: % Cobertura = Con servicio / Vendidos. TOTAL = SUM
B16: §5 Buckets de días | C16: Total por bucket = SUM marcas. Total con servicio = SUM buckets
B18: Caveat 2026-06 | C18: Corte parcial al 15-jun. Importes inconsistentes vs unidades. No citar el mes aislado sin validar con Inés.

Sheet Metodología
A1: Metodología · cómo se calculó cada número
A2: Cada hoja del libro usa fórmulas vivas: si editas un mes, los totales/ratios/% recalculan solos. Aquí está la receta exacta de cada cálculo, con la celda dónde lo verificas.
A4: 0. Fuente, periodo y filtros base
A5: Tema | B5: Detalle | C5: Cubo / Campo | D5: Notas
A6: Fuente | B6: BITAM Artus · cuenta jmorales@grupoplasencia.com (user 261 Pepe Morales) | C6: — | D6: Ingestado a D1 bitam-mkt
A7: Cubos | B7: 30003 Venta Autos · 30008 Venta Servicio y Refacciones | C7: 30003 + 30008 | D7: Re-extracción mensual del 30008 (workaround chunk mensual)
A8: Periodo | B8: 2025-01-01 a 2026-06-15 (corte parcial al 15-jun) | C8: D_25 Fecha Facturación | D8: Junio 2026 parcial — no citar el mes aislado sin validar con Inés
A9: Filtro Marca | B9: GAC · CHANGAN · GWM (Marca del auto, no Marca Sucursal) | C9: D_67 Marca | D9: Si interesa otro corte, mismos queries cambiando filtro
A10: Categoría 'Servicio' | B10: Público, Previa, Express, Reparación, Garantía, Aseguradora, Hojalatería, Estética | C10: D_50 Tipo Orden | D10: Excluye Internas, Devoluciones, Mostrador, Mayoreo, Accesorios, Llantas
A11: OR distinta | B11: DISTINCT por Folio Orden Reparación | C11: D_31 Folio OR | D11: En extracto v1 no existía; v2 sí
A13: §1 Ventas mensuales — cómo se calcula
A14: Métrica | B14: Fórmula en Excel | C14: Origen del dato | D14: Lectura
A15: Uds por marca por mes (B/C/D) | B15: Valor crudo del cubo 30003 (COUNT de VINs nuevos del mes × marca) | C15: 30003 → cubo_30003_ventas en D1 | D15: Filtrado por nuevo_usado='AUTOS NUEVOS' + marca chinas
A16: $ por marca por mes (E/F/G) | B16: Valor crudo del cubo 30003 (SUM de Importe Factura) | C16: 30003 · I_30217 / parsed REAL | D16: ='$250,000' → 250000 al ingestar a D1
A17: Total uds del mes (H) | B17: =B + C + D | C17: Fórmula viva | D17: Suma horizontal de las 3 marcas
A18: Total 2025 (fila 14) | B18: =SUM(B2:B13) por cada columna | C18: Fórmula viva | D18: Suma vertical de los 12 meses 2025
A19: Total 2026 YTD | B19: =SUM(2026-01 : 2026-06) por cada columna | C19: Fórmula viva | D19: Incluye junio parcial — bandera (*) en celda
A20: Acumulado 2025+26 YTD | B20: =Total 2025 + Total 2026 YTD por cada columna | C20: Fórmula viva | D20: Es el número que alimenta §3 y §4
A22: §2 OR Servicio mensuales — cómo se calcula
A23: Métrica | B23: Fórmula en Excel | C23: Origen del dato | D23: Lectura
A24: OR por marca por mes (B/C/D) | B24: Valor crudo del cubo 30008 (COUNT DISTINCT Folio OR del mes × marca) | C24: 30008 → cubo_30008_servicio en D1 | D24: Solo Tipo Orden 'Servicio' (lista §0). Excluye Internas, Devoluciones, Mostrador
A25: Total OR del mes (E) | B25: =B + C + D | C25: Fórmula viva | D25: Suma horizontal de las 3 marcas
A26: Total 2025 (fila 14) | B26: =SUM(B2:B13) por cada columna | C26: Fórmula viva | D26: Suma vertical de los 12 meses
A27: Total 2026 YTD | B27: =SUM(2026-01 : 2026-06) por cada columna | C27: Fórmula viva | D27: Incluye junio parcial
A28: Acumulado 2025+26 YTD | B28: =Total 2025 + Total 2026 YTD por cada columna | C28: Fórmula viva | D28: Es el número que alimenta §3
A30: §3 Ratio OR / Venta — cómo se calcula
A31: Métrica | B31: Fórmula en Excel | C31: Origen del dato | D31: Lectura
A32: OR distintas (col B) | B32: ='§2 OR Servicio mensuales'!<col_marca><fila acumulado> | C32: Link directo a §2 acumulado | D32: Si editas un mes en §2, este número cambia
A33: Uds vendidas (col C) | B33: ='§1 Ventas mensuales'!<col_marca><fila acumulado> | C33: Link directo a §1 acumulado | D33: Si editas un mes en §1, este número cambia
A34: Ratio OR/Venta (col D) | B34: =B / C | C34: Fórmula viva | D34: Velocidad de visita acumulada. NO es frecuencia por unidad (las OR incluyen autos de cohortes anteriores)
A36: §4 Valor refacciones — cómo se calcula
A37: Métrica | B37: Fórmula en Excel | C37: Origen del dato | D37: Lectura
A38: Servicio $ (col B) | B38: SUM del cubo 30008 indicador Servicio | C38: 30008 · I_30498 Vta $ Serv | D38: Mano de obra de servicio
A39: Refacciones $ (col C) | B39: SUM del cubo 30008 indicador Refacciones | C39: 30008 · I_30500 Vta $ Ref | D39: Piezas vendidas en OR de servicio
A40: Hojalatería $ (col D) | B40: SUM del cubo 30008 indicador Hojalatería y Pintura | C40: 30008 · I_30499 Vta $ HyP | D40: Solo HyP — GWM concentra 98% del total chinas, validar
A41: Total post-venta $ (col E) | B41: =B + C + D | C41: Fórmula viva | D41: Suma de las 3 cubetas monetarias
A42: Revenue venta $ (col F) | B42: ='§1 Ventas mensuales'!<col_marca_$><fila acumulado> | C42: Link a §1 acumulado | D42: El ingreso de venta de autos para esa marca
A43: % vs Revenue venta (col G) | B43: =E / F | C43: Fórmula viva | D43: Qué tan grande es post-venta vs venta. Bench NADA US es 8–12%; chinas en 1.71% — headroom estructural
A44: TOTAL CHINAS | B44: =SUM(B2:B4) por cada columna; % = E/F | C44: Fórmula viva | D44: Agregado de las 3 marcas
A46: §5 Tiempo a 1er servicio — cómo se calcula
...

Sheet §1 Ventas mensuales
A1: Mes | B1: CHANGAN uds | C1: GAC uds | D1: GWM uds | E1: CHANGAN $ | F1: GAC $ | G1: GWM $ | H1: Total uds
A2: 2025/01 | B2: 47 | C2: 151 | D2: 114 | E2: 17000000 | F2: 68000000 | G2: 47400000 | H2: =B2+C2+D2
A3: 2025/02 | B3: 61 | C3: 58 | D3: 117 | E3: 18600000 | F3: 27500000 | G3: 51400000 | H3: =B3+C3+D3
A4: 2025/03 | B4: 95 | C4: 75 | D4: 120 | E4: 31600000 | F4: 37500000 | G4: 49800000 | H4: =B4+C4+D4
A5: 2025/04 | B5: 106 | C5: 43 | D5: 104 | E5: 35200000 | F5: 17700000 | G5: 32100000 | H5: =B5+C5+D5
A6: 2025/05 | B6: 158 | C6: 82 | D6: 89 | E6: 49500000 | F6: 32900000 | G6: 32900000 | H6: =B6+C6+D6
A7: 2025/06 | B7: 138 | C7: 74 | D7: 111 | E7: 44400000 | F7: 36800000 | G7: 36300000 | H7: =B7+C7+D7
A8: 2025/07 | B8: 191 | C8: 110 | D8: 103 | E8: 60700000 | F8: 53800000 | G8: 45700000 | H8: =B8+C8+D8
A9: 2025/08 | B9: 207 | C9: 116 | D9: 148 | E9: 66600000 | F9: 55000000 | G9: 48600000 | H9: =B9+C9+D9
A10: 2025/09 | B10: 185 | C10: 107 | D10: 129 | E10: 65300000 | F10: 44300000 | G10: 43000000 | H10: =B10+C10+D10
A11: 2025/10 | B11: 216 | C11: 95 | D11: 106 | E11: 69700000 | F11: 34000000 | G11: 34600000 | H11: =B11+C11+D11
A12: 2025/11 | B12: 146 | C12: 86 | D12: 129 | E12: 49200000 | F12: 41700000 | G12: 62800000 | H12: =B12+C12+D12
A13: 2025/12 | B13: 191 | C13: 99 | D13: 136 | E13: 54400000 | F13: 40900000 | G13: 52300000 | H13: =B13+C13+D13
A14: Total 2025 | B14: =SUM(B2:B13) | C14: =SUM(C2:C13) | D14: =SUM(D2:D13) | E14: =SUM(E2:E13) | F14: =SUM(F2:F13) | G14: =SUM(G2:G13) | H14: =SUM(H2:H13)
A15: 2026/01 | B15: 121 | C15: 68 | D15: 114 | E15: 36600000 | F15: 28400000 | G15: 36900000 | H15: =B15+C15+D15
A16: 2026/02 | B16: 104 | C16: 84 | D16: 86 | E16: 35100000 | F16: 34700000 | G16: 37500000 | H16: =B16+C16+D16
A17: 2026/03 | B17: 155 | C17: 140 | D17: 94 | E17: 52900000 | F17: 60100000 | G17: 41400000 | H17: =B17+C17+D17
A18: 2026/04 | B18: 160 | C18: 92 | D18: 75 | E18: 48900000 | F18: 41100000 | G18: 28500000 | H18: =B18+C18+D18
A19: 2026/05 | B19: 133 | C19: 171 | D19: 77 | E19: 40900000 | F19: 73600000 | G19: 27400000 | H19: =B19+C19+D19
A20: 2026/06 * | B20: 45 | C20: 103 | D20: 20 | E20: 2100000 | F20: 6300000 | G20: 6900000 | H20: =B20+C20+D20
A21: Total 2026 YTD | B21: =SUM(B15:B20) | C21: =SUM(C15:C20) | D21: =SUM(D15:D20) | E21: =SUM(E15:E20) | F21: =SUM(F15:F20) | G21: =SUM(G15:G20) | H21: =SUM(H15:H20)
A22: Acumulado 2025+26 YTD | B22: =B14+B21 | C22: =C14+C21 | D22: =D14+D21 | E22: =E14+E21 | F22: =F14+F21 | G22: =G14+G21 | H22: =H14+H21
A24: (*) Junio 2026 parcial al 15-jun. Importes incompletos en DMS. Validar con Inés antes de citar.

Sheet §2 OR Servicio mensuales
A1: Mes | B1: CHANGAN OR | C1: GAC OR | D1: GWM OR | E1: Total OR
A2: 2025/01 | B2: 68 | C2: 90 | D2: 162 | E2: =B2+C2+D2
A3: 2025/02 | B3: 101 | C3: 104 | D3: 214 | E3: =B3+C3+D3
A4: 2025/03 | B4: 98 | C4: 255 | D4: 209 | E4: =B4+C4+D4
A5: 2025/04 | B5: 144 | C5: 234 | D5: 310 | E5: =B5+C5+D5
A6: 2025/05 | B6: 151 | C6: 271 | D6: 275 | E6: =B6+C6+D6
A7: 2025/06 | B7: 163 | C7: 218 | D7: 280 | E7: =B7+C7+D7
A8: 2025/07 | B8: 174 | C8: 251 | D8: 340 | E8: =B8+C8+D8
A9: 2025/08 | B9: 170 | C9: 244 | D9: 315 | E9: =B9+C9+D9
A10: 2025/09 | B10: 191 | C10: 299 | D10: 310 | E10: =B10+C10+D10
A11: 2025/10 | B11: 236 | C11: 332 | D11: 331 | E11: =B11+C11+D11
A12: 2025/11 | B12: 224 | C12: 286 | D12: 289 | E12: =B12+C12+D12
A13: 2025/12 | B13: 298 | C13: 308 | D13: 399 | E13: =B13+C13+D13
A14: Total 2025 | B14: =SUM(B2:B13) | C14: =SUM(C2:C13) | D14: =SUM(D2:D13) | E14: =SUM(E2:E13)
A15: 2026/01 | B15: 294 | C15: 376 | D15: 447 | E15: =B15+C15+D15
A16: 2026/02 | B16: 267 | C16: 396 | D16: 385 | E16: =B16+C16+D16
A17: 2026/03 | B17: 320 | C17: 416 | D17: 436 | E17: =B17+C17+D17
A18: 2026/04 | B18: 285 | C18: 420 | D18: 404 | E18: =B18+C18+D18
A19: 2026/05 | B19: 364 | C19: 406 | D19: 413 | E19: =B19+C19+D19
A20: 2026/06 * | B20: 156 | C20: 194 | D20: 244 | E20: =B20+C20+D20
A21: Total 2026 YTD | B21: =SUM(B15:B20) | C21: =SUM(C15:C20) | D21: =SUM(D15:D20) | E21: =SUM(E15:E20)
A22: Acumulado 2025+26 YTD | B22: =B14+B21 | C22: =C14+C21 | D22: =D14+D21 | E22: =E14+E21
A24: Filtro: Servicio (Público, Previa, Express, Reparación, Garantía, Aseguradora, Hojalatería, Estética). Excluye Internas, Devoluciones, Mostrador.

Sheet §3 Ratio OR sobre Venta
A1: Marca | B1: OR distintas | C1: Uds vendidas | D1: Ratio OR/Venta
A2: CHANGAN | B2: ='§2 OR Servicio mensuales'!B22 | C2: ='§1 Ventas mensuales'!B22 | D2: =B2/C2
A3: GAC | B3: ='§2 OR Servicio mensuales'!C22 | C3: ='§1 Ventas mensuales'!C22 | D3: =B3/C3
A4: GWM | B4: ='§2 OR Servicio mensuales'!D22 | C4: ='§1 Ventas mensuales'!D22 | D4: =B4/C4
A6: Ratio = OR del periodo / autos vendidos del periodo. Incluye autos de cohortes anteriores; no es frecuencia por unidad.

Sheet §4 Valor refacciones
A1: Marca | B1: Servicio $ | C1: Refacciones $ | D1: Hojalatería $ | E1: Total post-venta $ | F1: Revenue venta $ | G1: % vs Revenue venta
A2: CHANGAN | B2: 3246432 | C2: 3895092 | D2: 87638 | E2: =B2+C2+D2 | F2: ='§1 Ventas mensuales'!E22 | G2: =E2/F2
A3: GAC | B3: 3651810 | C3: 8491002 | D3: 34591 | E3: =B3+C3+D3 | F3: ='§1 Ventas mensuales'!F22 | G3: =E3/F3
A4: GWM | B4: 4817297 | C4: 10008087 | D4: 6143904 | E4: =B4+C4+D4 | F4: ='§1 Ventas mensuales'!G22 | G4: =E4/F4
A5: TOTAL CHINAS | B5: =SUM(B2:B4) | C5: =SUM(C2:C4) | D5: =SUM(D2:D4) | E5: =SUM(E2:E4) | F5: =SUM(F2:F4) | G5: =E5/F5
A7: Indicadores cubo 30008: I_30498 Servicio, I_30500 Refacciones, I_30499 Hojalatería. Revenue venta linkeado a §1 acumulado.

Sheet §5 Tiempo a 1er servicio
A1: Marca | B1: Vendidos en periodo | C1: Con ≥1 servicio | D1: % Cobertura | E1: Promedio días | F1: Mediana días | G1: Min | H1: Max
A2: CHANGAN | B2: 1819 | C2: 1205 | D2: =C2/B2 | E2: 91 | F2: 46 | G2: 0 | H2: 461
A3: GAC | B3: 1402 | C3: 1055 | D3: =C3/B3 | E3: 66 | F3: 46 | G3: 0 | H3: 481
A4: GWM | B4: 1333 | C4: 1049 | D4: =C4/B4 | E4: 73 | F4: 27 | G4: 0 | H4: 437
A5: TOTAL CHINAS | B5: =SUM(B2:B4) | C5: =SUM(C2:C4) | D5: =C5/B5 | E5: =ROUND(SUMPRODUCT(E2:E4,C2:C4)/C5,0) | F5: 40 | G5: =MIN(G2:G4) | H5: =MAX(H2:H4)
A7: Método: join VIN entre 30003 y 30008. Solo Servicio. fecha_servicio ≥ fecha_venta. Mediana del total = valor del reporte (no es agregable con fórmula).

Sheet §5 Buckets de días
A1: Bucket | B1: CHANGAN | C1: GAC | D1: GWM | E1: Total
A2: 0-30 d | B2: 533 | C2: 450 | D2: 585 | E2: =B2+C2+D2
A3: 31-90 d | B3: 187 | C3: 260 | D3: 175 | E3: =B3+C3+D3
A4: 91-180 d | B4: 214 | C4: 294 | D4: 106 | E4: =B4+C4+D4
A5: 181-365 d | B5: 266 | C5: 49 | D5: 176 | E5: =B5+C5+D5
A6: 366+ d | B6: 5 | C6: 2 | D6: 7 | E6: =B6+C6+D6
A7: Total con servicio | B7: =SUM(B2:B6) | C7: =SUM(C2:C6) | D7: =SUM(D2:D6) | E7: =SUM(E2:E6)
A9: Pico 0–30 d probablemente incluye PDI, entregas, garantía inicial y cortesía — no necesariamente mantenimiento programado.
